<?xml version="1.0" ?>
<robot name="sence_leg" xmlns:xacro="http://www.ros.org/wiki/xacro">

<xacro:include filename="$(find sence_leg_description)/urdf/sence_leg.trans" />
<xacro:include filename="$(find sence_leg_description)/urdf/sence_leg.gazebo" />
<xacro:macro name="sence_leg_macro" params="prefix parent adjT adjR">
<link name="${prefix}base_link">
  <inertial>
    <origin xyz="0.029044932513473305 0.010265080427010284 -0.03814827760382364" rpy="0 0 0"/>
    <mass value="0.15187448298114298"/>
    <inertia ixx="5.3e-05" iyy="6.1e-05" izz="6.9e-05" ixy="-6e-06" iyz="0.0" ixz="0.0"/>
  </inertial>
  <visual>
    <origin xyz="0 0 0" rpy="0 0 0"/>
    <geometry>
      <mesh filename="package://sence_leg_description/meshes/base_link.stl" scale="0.001 0.001 0.001"/>
    </geometry>
    <material name="silver"/>
  </visual>
  <collision>
    <origin xyz="0 0 0" rpy="0 0 0"/>
    <geometry>
      <mesh filename="package://sence_leg_description/meshes/base_link.stl" scale="0.001 0.001 0.001"/>
    </geometry>
  </collision>
</link>

<link name="${prefix}HMMR_Leg_J2_v1_1">
  <inertial>
    <origin xyz="-0.04078394902352935 -0.013231283994066126 0.00021684450055575039" rpy="0 0 0"/>
    <mass value="0.09734685103972182"/>
    <inertia ixx="2.2e-05" iyy="3.6e-05" izz="4e-05" ixy="-2e-06" iyz="0.0" ixz="0.0"/>
  </inertial>
  <visual>
    <origin xyz="-0.01348 -0.002676 0.038139" rpy="0 0 0"/>
    <geometry>
      <mesh filename="package://sence_leg_description/meshes/HMMR_Leg_J2_v1_1.stl" scale="0.001 0.001 0.001"/>
    </geometry>
    <material name="silver"/>
  </visual>
  <collision>
    <origin xyz="-0.01348 -0.002676 0.038139" rpy="0 0 0"/>
    <geometry>
      <mesh filename="package://sence_leg_description/meshes/HMMR_Leg_J2_v1_1.stl" scale="0.001 0.001 0.001"/>
    </geometry>
  </collision>
</link>

<link name="${prefix}HMMR_Leg_J3_v1_1">
  <inertial>
    <origin xyz="-0.05832553714381231 -0.021436456555043018 0.0024477833961314005" rpy="0 0 0"/>
    <mass value="0.12243154933451669"/>
    <inertia ixx="3.6e-05" iyy="9.7e-05" izz="9.9e-05" ixy="1e-05" iyz="-0.0" ixz="2e-06"/>
  </inertial>
  <visual>
    <origin xyz="0.020447 -0.009456 0.037939" rpy="0 0 0"/>
    <geometry>
      <mesh filename="package://sence_leg_description/meshes/HMMR_Leg_J3_v1_1.stl" scale="0.001 0.001 0.001"/>
    </geometry>
    <material name="silver"/>
  </visual>
  <collision>
    <origin xyz="0.020447 -0.009456 0.037939" rpy="0 0 0"/>
    <geometry>
      <mesh filename="package://sence_leg_description/meshes/HMMR_Leg_J3_v1_1.stl" scale="0.001 0.001 0.001"/>
    </geometry>
  </collision>
</link>

<link name="${prefix}HMMR_Leg_J4_1">
   <inertial>
    <origin xyz="-0.05691796302157942 0.007704167559869515 0.01964749184467182" rpy="0 0 0"/>
    <mass value="0.05742201556545181"/>
    <inertia ixx="2e-05" iyy="5.7e-05" izz="5.2e-05" ixy="8e-06" iyz="-0.0" ixz="1e-06"/>
  </inertial>
  <visual>
    <origin xyz="0.079954 0.010544 0.057414" rpy="0 0 0"/>
    <geometry>
      <mesh filename="package://sence_leg_description/meshes/HMMR_Leg_J4_v1_1.stl" scale="0.001 0.001 0.001"/>
    </geometry>
    <material name="silver"/>
  </visual>
  <collision>
    <origin xyz="0.079954 0.010544 0.057414" rpy="0 0 0"/>
    <geometry>
      <mesh filename="package://sence_leg_description/meshes/HMMR_Leg_J4_v1_1.stl" scale="0.001 0.001 0.001"/>
    </geometry>
  </collision>
</link>

<joint name="${prefix}system_connection" type="fixed">
  <origin rpy="${adjR}" xyz="${adjT}"/>
  <parent link="${parent}"/>
  <child link="${prefix}base_link"/>
</joint>

<joint name="${prefix}Rev1" type="continuous">
  <origin xyz="0.01348 0.002676 -0.038139" rpy="0 0 0"/>
  <parent link="${prefix}base_link"/>
  <child link="${prefix}HMMR_Leg_J2_v1_1"/>
  <axis xyz="1.0 0.0 -0.0"/>
</joint>

<joint name="${prefix}Rev2" type="revolute">
  <origin xyz="-0.033927 0.00678 0.0002" rpy="0 0 0"/>
  <parent link="${prefix}HMMR_Leg_J2_v1_1"/>
  <child link="${prefix}HMMR_Leg_J3_v1_1"/>
  <axis xyz="0.0 -1.0 0.0"/>
  <limit upper="1.919862" lower="-1.919862" effort="100" velocity="100"/>
</joint>

<joint name="${prefix}Rev3" type="revolute">
  <origin xyz="-0.059507 -0.02 -0.019475" rpy="0 0 0"/>
  <parent link="${prefix}HMMR_Leg_J3_v1_1"/>
  <child link="${prefix}HMMR_Leg_J4_1"/>
  <axis xyz="-0.0 -0.0 1.0"/>
  <limit upper="2.094395" lower="-2.094395" effort="100" velocity="100"/>
</joint>
</xacro:macro>
</robot>
