<?xml version="1.0"?>
<robot xmlns:xacro="http://www.ros.org/wiki/xacro">

    <xacro:macro name="wrist" params="name parent *origin">

        <xacro:include filename="$(find sence_description)/urdf/common/math.urdf.xacro" />

        <!-- revolute attachment joint -->
        <joint name="${name}_joint" type="revolute" >
            <parent link="${parent}" />
            <child link="${name}" />
            <xacro:insert_block name="origin" />
            <axis xyz="0 0 1" rpy="0 0 0" />
            <limit upper="2.75" lower="-2.75" effort="2.5" velocity="5.5" />
        </joint>

        <!-- wrist link -->
        <link name="${name}">
            <!-- visual -->
            <visual>
                <geometry>
                    <!-- <mesh filename="package://sence_description/meshes/wrist.stl"/> -->
                    <mesh filename="package://sence_description/meshes/wrist.dae"/>
                </geometry>
                <material name="LightGrey2"/>
            </visual>

            <!-- collision -->
            <xacro:property name="collision_box_x" value="0.075" />
            <xacro:property name="collision_box_y" value="0.055" />
            <xacro:property name="collision_box_z" value="0.035" />

            <collision >
                <geometry>
                    <!-- <box size="${collision_box_x} ${collision_box_y} ${collision_box_z}"/> -->
                    <mesh filename="package://sence_description/meshes/wrist.stl"/>
                </geometry>
            </collision>

            <!-- inertia -->
            <inertial>
                <mass value="0.074" />
                <origin xyz="0.061081 0.000014 0.003984" rpy="0 0 0" />
                <inertia ixx="0.000010616" ixy="0.000000044" ixz="0.0000180236" iyy="0.000429333" iyz="0.000000005" izz="0.000424345" />
            </inertial>
        </link>

        <!-- end ground contact reference frame using a link-->
        <link name="${name}_contact"/>
        <joint name="${name}_contact_joint" type="fixed">
            <parent link="${name}" />
            <child link="${name}_contact" />
            <origin xyz="0.193702 0 0" rpy="0 0 0" />
        </joint>


        <!-- transmission -->
        <transmission name="${name}_trans">
            <type>transmission_interface/SimpleTransmission</type>
            <joint name="${name}_joint">
                <hardwareInterface>hardware_interface/PositionJointInterface</hardwareInterface>
            </joint>
            <actuator name="${name}_motor">
                <mechanicalReduction>1.0</mechanicalReduction>
                <!-- <hardwareInterface>hardware_interface/PositionJointInterface</hardwareInterface> -->
            </actuator>
        </transmission>

        <!-- gazebo colour -->
        <gazebo reference="${name}">
            <material>Gazebo/Grey</material>
        </gazebo>

        <!-- gazebo physics properties -->
        <!-- <gazebo reference="${name}"> -->
			<!-- <mu1 value="0.98"/> -->
			<!-- <mu2 value="0.98"/> -->
			<!-- <kp value="1000000.0" /> -->
			<!-- <kd value="100.0" /> -->
			<!-- <fdir1 value="1 0 0"/> -->
		<!-- </gazebo> -->

    </xacro:macro>

</robot>
