<?xml version="1.0" ?>
<!-- =================================================================================== -->
<!-- |    This document was autogenerated by xacro from /home/catkin_ws/src/sence_paper/sence_main_description/urdf/sence_comb.xacro | -->
<!-- |    EDITING THIS FILE BY HAND IS NOT RECOMMENDED                                 | -->
<!-- =================================================================================== -->
<robot name="sence_main">
  <transmission name="Rev1_tran">
    <type>transmission_interface/SimpleTransmission</type>
    <joint name="Rev1">
      <hardwareInterface>hardware_interface/EffortJointInterface</hardwareInterface>
    </joint>
    <actuator name="Rev1_actr">
      <hardwareInterface>hardware_interface/EffortJointInterface</hardwareInterface>
      <mechanicalReduction>1</mechanicalReduction>
    </actuator>
  </transmission>
  <transmission name="Rev2_tran">
    <type>transmission_interface/SimpleTransmission</type>
    <joint name="Rev2">
      <hardwareInterface>hardware_interface/EffortJointInterface</hardwareInterface>
    </joint>
    <actuator name="Rev2_actr">
      <hardwareInterface>hardware_interface/EffortJointInterface</hardwareInterface>
      <mechanicalReduction>1</mechanicalReduction>
    </actuator>
  </transmission>
  <transmission name="Rev3_tran">
    <type>transmission_interface/SimpleTransmission</type>
    <joint name="Rev3">
      <hardwareInterface>hardware_interface/EffortJointInterface</hardwareInterface>
    </joint>
    <actuator name="Rev3_actr">
      <hardwareInterface>hardware_interface/EffortJointInterface</hardwareInterface>
      <mechanicalReduction>1</mechanicalReduction>
    </actuator>
  </transmission>
  <gazebo>
    <plugin filename="libgazebo_ros_control.so" name="control"/>
  </gazebo>
  <gazebo reference="base_link">
    <material>Gazebo/Silver</material>
    <mu1>0.2</mu1>
    <mu2>0.2</mu2>
    <selfCollide>true</selfCollide>
    <gravity>true</gravity>
  </gazebo>
  <gazebo reference="HMMR_Leg_J2_v1_1">
    <material>Gazebo/Silver</material>
    <mu1>0.2</mu1>
    <mu2>0.2</mu2>
    <selfCollide>true</selfCollide>
  </gazebo>
  <gazebo reference="HMMR_Leg_J3_v1_1">
    <material>Gazebo/Silver</material>
    <mu1>0.2</mu1>
    <mu2>0.2</mu2>
    <selfCollide>true</selfCollide>
  </gazebo>
  <gazebo reference="HMMR_Leg_J4_1">
    <material>Gazebo/Silver</material>
    <mu1>0.2</mu1>
    <mu2>0.2</mu2>
    <selfCollide>true</selfCollide>
  </gazebo>
  <material name="silver">
    <color rgba="0.700 0.700 0.700 1.000"/>
  </material>
  <gazebo>
    <plugin filename="libgazebo_ros_control.so" name="control"/>
  </gazebo>
  <gazebo reference="base_link">
    <material>Gazebo/Silver</material>
    <mu1>0.2</mu1>
    <mu2>0.2</mu2>
    <selfCollide>true</selfCollide>
    <gravity>true</gravity>
  </gazebo>
  <link name="base_link">
    <inertial>
      <origin rpy="0 0 0" xyz="-0.0003058772493282508 -8.555215015878667e-05 -7.892579365353808e-05"/>
      <mass value="0.866383082373337"/>
      <inertia ixx="0.012736" ixy="-0.0" ixz="0.0" iyy="0.003778" iyz="0.0" izz="0.016249"/>
    </inertial>
    <visual>
      <origin rpy="0 0 0" xyz="0 0 0"/>
      <geometry>
        <mesh filename="package://sence_main_description/meshes/base_link.stl" scale="0.001 0.001 0.001"/>
      </geometry>
      <material name="silver"/>
    </visual>
    <collision>
      <origin rpy="0 0 0" xyz="0 0 0"/>
      <geometry>
        <mesh filename="package://sence_main_description/meshes/base_link.stl" scale="0.001 0.001 0.001"/>
      </geometry>
    </collision>
  </link>
  <link name="back_right_leg_base_link">
    <inertial>
      <origin rpy="0 0 0" xyz="-0.028184578381233765 0.0020392786644214244 -9.813214185615953e-06"/>
      <mass value="0.15187448298114298"/>
      <inertia ixx="5.3e-05" ixy="-6e-06" ixz="0.0" iyy="6.1e-05" iyz="0.0" izz="6.9e-05"/>
    </inertial>
    <visual>
      <origin rpy="0 0 0" xyz="0 0 0"/>
      <geometry>
        <mesh filename="package://sence_leg_description/meshes/base_link.stl" scale="0.001 0.001 0.001"/>
      </geometry>
      <material name="silver"/>
    </visual>
    <collision>
      <origin rpy="0 0 0" xyz="0 0 0"/>
      <geometry>
        <mesh filename="package://sence_leg_description/meshes/base_link.stl" scale="0.001 0.001 0.001"/>
      </geometry>
    </collision>
  </link>
  <link name="back_right_leg_HMMR_Leg_J2_v1_1">
    <inertial>
      <origin rpy="0 0 0" xyz="-0.04078345991823647 -0.01323108575665483 0.00021630889019305232"/>
      <mass value="0.09734685103972182"/>
      <inertia ixx="2.2e-05" ixy="-2e-06" ixz="0.0" iyy="3.6e-05" iyz="0.0" izz="4e-05"/>
    </inertial>
    <visual>
      <origin rpy="0 0 0" xyz="0.04375 0.00555 0.0"/>
      <geometry>
        <mesh filename="package://sence_leg_description/meshes/HMMR_Leg_J2_v1_1.stl" scale="0.001 0.001 0.001"/>
      </geometry>
      <material name="silver"/>
    </visual>
    <collision>
      <origin rpy="0 0 0" xyz="0.04375 0.00555 0.0"/>
      <geometry>
        <mesh filename="package://sence_leg_description/meshes/HMMR_Leg_J2_v1_1.stl" scale="0.001 0.001 0.001"/>
      </geometry>
    </collision>
  </link>
  <link name="back_right_leg_HMMR_Leg_J3_v1_1">
    <inertial>
      <origin rpy="0 0 0" xyz="-0.06366993215147018 -0.021943102238793904 0.0024098327148608222"/>
      <mass value="0.1208747488020619"/>
      <inertia ixx="3.4e-05" ixy="1.4e-05" ixz="2e-06" iyy="0.000102" iyz="-1e-06" izz="0.000104"/>
    </inertial>
    <visual>
      <origin rpy="0 0 0" xyz="0.077676 -0.00123 -0.0002"/>
      <geometry>
        <mesh filename="package://sence_leg_description/meshes/HMMR_Leg_J3_v1_1.stl" scale="0.001 0.001 0.001"/>
      </geometry>
      <material name="silver"/>
    </visual>
    <collision>
      <origin rpy="0 0 0" xyz="0.077676 -0.00123 -0.0002"/>
      <geometry>
        <mesh filename="package://sence_leg_description/meshes/HMMR_Leg_J3_v1_1.stl" scale="0.001 0.001 0.001"/>
      </geometry>
    </collision>
  </link>
  <link name="back_right_leg_HMMR_Leg_J4_1">
    <inertial>
      <origin rpy="0 0 0" xyz="-0.06827232180237036 0.01066109112327507 0.02089322420417813"/>
      <mass value="0.052701725493830516"/>
      <inertia ixx="1.8e-05" ixy="1.4e-05" ixz="-1e-06" iyy="7.3e-05" iyz="0.0" izz="7.2e-05"/>
    </inertial>
    <visual>
      <origin rpy="0 0 0" xyz="0.142683 0.01877 0.019275"/>
      <geometry>
        <mesh filename="package://sence_leg_description/meshes/HMMR_Leg_J4_1.stl" scale="0.001 0.001 0.001"/>
      </geometry>
      <material name="silver"/>
    </visual>
    <collision>
      <origin rpy="0 0 0" xyz="0.142683 0.01877 0.019275"/>
      <geometry>
        <mesh filename="package://sence_leg_description/meshes/HMMR_Leg_J4_1.stl" scale="0.001 0.001 0.001"/>
      </geometry>
    </collision>
  </link>
  <joint name="back_right_leg_system_connection" type="fixed">
    <origin rpy="0 3.14159 0" xyz="0.20 -0.15 0"/>
    <parent link="base_link"/>
    <child link="back_right_leg_base_link"/>
  </joint>
  <joint name="back_right_leg_Rev1" type="continuous">
    <origin rpy="0 0 0" xyz="-0.04375 -0.00555 0.0"/>
    <parent link="back_right_leg_base_link"/>
    <child link="back_right_leg_HMMR_Leg_J2_v1_1"/>
    <axis xyz="1.0 0.0 0.0"/>
  </joint>
  <joint name="back_right_leg_Rev2" type="revolute">
    <origin rpy="0 0 0" xyz="-0.033926 0.00678 0.0002"/>
    <parent link="back_right_leg_HMMR_Leg_J2_v1_1"/>
    <child link="back_right_leg_HMMR_Leg_J3_v1_1"/>
    <axis xyz="0.0 -1.0 0.0"/>
    <limit effort="100" lower="-1.919862" upper="1.919862" velocity="100"/>
  </joint>
  <joint name="back_right_leg_Rev3" type="revolute">
    <origin rpy="0 0 0" xyz="-0.065007 -0.02 -0.019475"/>
    <parent link="back_right_leg_HMMR_Leg_J3_v1_1"/>
    <child link="back_right_leg_HMMR_Leg_J4_1"/>
    <axis xyz="-0.0 -0.0 1.0"/>
    <limit effort="100" lower="-2.268928" upper="2.356194" velocity="100"/>
  </joint>
  <link name="back_left_leg_base_link">
    <inertial>
      <origin rpy="0 0 0" xyz="-0.028184578381233765 0.0020392786644214244 -9.813214185615953e-06"/>
      <mass value="0.15187448298114298"/>
      <inertia ixx="5.3e-05" ixy="-6e-06" ixz="0.0" iyy="6.1e-05" iyz="0.0" izz="6.9e-05"/>
    </inertial>
    <visual>
      <origin rpy="0 0 0" xyz="0 0 0"/>
      <geometry>
        <mesh filename="package://sence_leg_description/meshes/base_link.stl" scale="0.001 0.001 0.001"/>
      </geometry>
      <material name="silver"/>
    </visual>
    <collision>
      <origin rpy="0 0 0" xyz="0 0 0"/>
      <geometry>
        <mesh filename="package://sence_leg_description/meshes/base_link.stl" scale="0.001 0.001 0.001"/>
      </geometry>
    </collision>
  </link>
  <link name="back_left_leg_HMMR_Leg_J2_v1_1">
    <inertial>
      <origin rpy="0 0 0" xyz="-0.04078345991823647 -0.01323108575665483 0.00021630889019305232"/>
      <mass value="0.09734685103972182"/>
      <inertia ixx="2.2e-05" ixy="-2e-06" ixz="0.0" iyy="3.6e-05" iyz="0.0" izz="4e-05"/>
    </inertial>
    <visual>
      <origin rpy="0 0 0" xyz="0.04375 0.00555 0.0"/>
      <geometry>
        <mesh filename="package://sence_leg_description/meshes/HMMR_Leg_J2_v1_1.stl" scale="0.001 0.001 0.001"/>
      </geometry>
      <material name="silver"/>
    </visual>
    <collision>
      <origin rpy="0 0 0" xyz="0.04375 0.00555 0.0"/>
      <geometry>
        <mesh filename="package://sence_leg_description/meshes/HMMR_Leg_J2_v1_1.stl" scale="0.001 0.001 0.001"/>
      </geometry>
    </collision>
  </link>
  <link name="back_left_leg_HMMR_Leg_J3_v1_1">
    <inertial>
      <origin rpy="0 0 0" xyz="-0.06366993215147018 -0.021943102238793904 0.0024098327148608222"/>
      <mass value="0.1208747488020619"/>
      <inertia ixx="3.4e-05" ixy="1.4e-05" ixz="2e-06" iyy="0.000102" iyz="-1e-06" izz="0.000104"/>
    </inertial>
    <visual>
      <origin rpy="0 0 0" xyz="0.077676 -0.00123 -0.0002"/>
      <geometry>
        <mesh filename="package://sence_leg_description/meshes/HMMR_Leg_J3_v1_1.stl" scale="0.001 0.001 0.001"/>
      </geometry>
      <material name="silver"/>
    </visual>
    <collision>
      <origin rpy="0 0 0" xyz="0.077676 -0.00123 -0.0002"/>
      <geometry>
        <mesh filename="package://sence_leg_description/meshes/HMMR_Leg_J3_v1_1.stl" scale="0.001 0.001 0.001"/>
      </geometry>
    </collision>
  </link>
  <link name="back_left_leg_HMMR_Leg_J4_1">
    <inertial>
      <origin rpy="0 0 0" xyz="-0.06827232180237036 0.01066109112327507 0.02089322420417813"/>
      <mass value="0.052701725493830516"/>
      <inertia ixx="1.8e-05" ixy="1.4e-05" ixz="-1e-06" iyy="7.3e-05" iyz="0.0" izz="7.2e-05"/>
    </inertial>
    <visual>
      <origin rpy="0 0 0" xyz="0.142683 0.01877 0.019275"/>
      <geometry>
        <mesh filename="package://sence_leg_description/meshes/HMMR_Leg_J4_1.stl" scale="0.001 0.001 0.001"/>
      </geometry>
      <material name="silver"/>
    </visual>
    <collision>
      <origin rpy="0 0 0" xyz="0.142683 0.01877 0.019275"/>
      <geometry>
        <mesh filename="package://sence_leg_description/meshes/HMMR_Leg_J4_1.stl" scale="0.001 0.001 0.001"/>
      </geometry>
    </collision>
  </link>
  <joint name="back_left_leg_system_connection" type="fixed">
    <origin rpy="0 0 0" xyz="-0.20 -0.15 0"/>
    <parent link="base_link"/>
    <child link="back_left_leg_base_link"/>
  </joint>
  <joint name="back_left_leg_Rev1" type="continuous">
    <origin rpy="0 0 0" xyz="-0.04375 -0.00555 0.0"/>
    <parent link="back_left_leg_base_link"/>
    <child link="back_left_leg_HMMR_Leg_J2_v1_1"/>
    <axis xyz="1.0 0.0 0.0"/>
  </joint>
  <joint name="back_left_leg_Rev2" type="revolute">
    <origin rpy="0 0 0" xyz="-0.033926 0.00678 0.0002"/>
    <parent link="back_left_leg_HMMR_Leg_J2_v1_1"/>
    <child link="back_left_leg_HMMR_Leg_J3_v1_1"/>
    <axis xyz="0.0 -1.0 0.0"/>
    <limit effort="100" lower="-1.919862" upper="1.919862" velocity="100"/>
  </joint>
  <joint name="back_left_leg_Rev3" type="revolute">
    <origin rpy="0 0 0" xyz="-0.065007 -0.02 -0.019475"/>
    <parent link="back_left_leg_HMMR_Leg_J3_v1_1"/>
    <child link="back_left_leg_HMMR_Leg_J4_1"/>
    <axis xyz="-0.0 -0.0 1.0"/>
    <limit effort="100" lower="-2.268928" upper="2.356194" velocity="100"/>
  </joint>
  <link name="front_right_leg_base_link">
    <inertial>
      <origin rpy="0 0 0" xyz="-0.028184578381233765 0.0020392786644214244 -9.813214185615953e-06"/>
      <mass value="0.15187448298114298"/>
      <inertia ixx="5.3e-05" ixy="-6e-06" ixz="0.0" iyy="6.1e-05" iyz="0.0" izz="6.9e-05"/>
    </inertial>
    <visual>
      <origin rpy="0 0 0" xyz="0 0 0"/>
      <geometry>
        <mesh filename="package://sence_leg_description/meshes/base_link.stl" scale="0.001 0.001 0.001"/>
      </geometry>
      <material name="silver"/>
    </visual>
    <collision>
      <origin rpy="0 0 0" xyz="0 0 0"/>
      <geometry>
        <mesh filename="package://sence_leg_description/meshes/base_link.stl" scale="0.001 0.001 0.001"/>
      </geometry>
    </collision>
  </link>
  <link name="front_right_leg_HMMR_Leg_J2_v1_1">
    <inertial>
      <origin rpy="0 0 0" xyz="-0.04078345991823647 -0.01323108575665483 0.00021630889019305232"/>
      <mass value="0.09734685103972182"/>
      <inertia ixx="2.2e-05" ixy="-2e-06" ixz="0.0" iyy="3.6e-05" iyz="0.0" izz="4e-05"/>
    </inertial>
    <visual>
      <origin rpy="0 0 0" xyz="0.04375 0.00555 0.0"/>
      <geometry>
        <mesh filename="package://sence_leg_description/meshes/HMMR_Leg_J2_v1_1.stl" scale="0.001 0.001 0.001"/>
      </geometry>
      <material name="silver"/>
    </visual>
    <collision>
      <origin rpy="0 0 0" xyz="0.04375 0.00555 0.0"/>
      <geometry>
        <mesh filename="package://sence_leg_description/meshes/HMMR_Leg_J2_v1_1.stl" scale="0.001 0.001 0.001"/>
      </geometry>
    </collision>
  </link>
  <link name="front_right_leg_HMMR_Leg_J3_v1_1">
    <inertial>
      <origin rpy="0 0 0" xyz="-0.06366993215147018 -0.021943102238793904 0.0024098327148608222"/>
      <mass value="0.1208747488020619"/>
      <inertia ixx="3.4e-05" ixy="1.4e-05" ixz="2e-06" iyy="0.000102" iyz="-1e-06" izz="0.000104"/>
    </inertial>
    <visual>
      <origin rpy="0 0 0" xyz="0.077676 -0.00123 -0.0002"/>
      <geometry>
        <mesh filename="package://sence_leg_description/meshes/HMMR_Leg_J3_v1_1.stl" scale="0.001 0.001 0.001"/>
      </geometry>
      <material name="silver"/>
    </visual>
    <collision>
      <origin rpy="0 0 0" xyz="0.077676 -0.00123 -0.0002"/>
      <geometry>
        <mesh filename="package://sence_leg_description/meshes/HMMR_Leg_J3_v1_1.stl" scale="0.001 0.001 0.001"/>
      </geometry>
    </collision>
  </link>
  <link name="front_right_leg_HMMR_Leg_J4_1">
    <inertial>
      <origin rpy="0 0 0" xyz="-0.06827232180237036 0.01066109112327507 0.02089322420417813"/>
      <mass value="0.052701725493830516"/>
      <inertia ixx="1.8e-05" ixy="1.4e-05" ixz="-1e-06" iyy="7.3e-05" iyz="0.0" izz="7.2e-05"/>
    </inertial>
    <visual>
      <origin rpy="0 0 0" xyz="0.142683 0.01877 0.019275"/>
      <geometry>
        <mesh filename="package://sence_leg_description/meshes/HMMR_Leg_J4_1.stl" scale="0.001 0.001 0.001"/>
      </geometry>
      <material name="silver"/>
    </visual>
    <collision>
      <origin rpy="0 0 0" xyz="0.142683 0.01877 0.019275"/>
      <geometry>
        <mesh filename="package://sence_leg_description/meshes/HMMR_Leg_J4_1.stl" scale="0.001 0.001 0.001"/>
      </geometry>
    </collision>
  </link>
  <joint name="front_right_leg_system_connection" type="fixed">
    <origin rpy="3.14159 3.14159 0" xyz="0.20 0.15 0"/>
    <parent link="base_link"/>
    <child link="front_right_leg_base_link"/>
  </joint>
  <joint name="front_right_leg_Rev1" type="continuous">
    <origin rpy="0 0 0" xyz="-0.04375 -0.00555 0.0"/>
    <parent link="front_right_leg_base_link"/>
    <child link="front_right_leg_HMMR_Leg_J2_v1_1"/>
    <axis xyz="1.0 0.0 0.0"/>
  </joint>
  <joint name="front_right_leg_Rev2" type="revolute">
    <origin rpy="0 0 0" xyz="-0.033926 0.00678 0.0002"/>
    <parent link="front_right_leg_HMMR_Leg_J2_v1_1"/>
    <child link="front_right_leg_HMMR_Leg_J3_v1_1"/>
    <axis xyz="0.0 -1.0 0.0"/>
    <limit effort="100" lower="-1.919862" upper="1.919862" velocity="100"/>
  </joint>
  <joint name="front_right_leg_Rev3" type="revolute">
    <origin rpy="0 0 0" xyz="-0.065007 -0.02 -0.019475"/>
    <parent link="front_right_leg_HMMR_Leg_J3_v1_1"/>
    <child link="front_right_leg_HMMR_Leg_J4_1"/>
    <axis xyz="-0.0 -0.0 1.0"/>
    <limit effort="100" lower="-2.268928" upper="2.356194" velocity="100"/>
  </joint>
  <link name="front_left_leg_base_link">
    <inertial>
      <origin rpy="0 0 0" xyz="-0.028184578381233765 0.0020392786644214244 -9.813214185615953e-06"/>
      <mass value="0.15187448298114298"/>
      <inertia ixx="5.3e-05" ixy="-6e-06" ixz="0.0" iyy="6.1e-05" iyz="0.0" izz="6.9e-05"/>
    </inertial>
    <visual>
      <origin rpy="0 0 0" xyz="0 0 0"/>
      <geometry>
        <mesh filename="package://sence_leg_description/meshes/base_link.stl" scale="0.001 0.001 0.001"/>
      </geometry>
      <material name="silver"/>
    </visual>
    <collision>
      <origin rpy="0 0 0" xyz="0 0 0"/>
      <geometry>
        <mesh filename="package://sence_leg_description/meshes/base_link.stl" scale="0.001 0.001 0.001"/>
      </geometry>
    </collision>
  </link>
  <link name="front_left_leg_HMMR_Leg_J2_v1_1">
    <inertial>
      <origin rpy="0 0 0" xyz="-0.04078345991823647 -0.01323108575665483 0.00021630889019305232"/>
      <mass value="0.09734685103972182"/>
      <inertia ixx="2.2e-05" ixy="-2e-06" ixz="0.0" iyy="3.6e-05" iyz="0.0" izz="4e-05"/>
    </inertial>
    <visual>
      <origin rpy="0 0 0" xyz="0.04375 0.00555 0.0"/>
      <geometry>
        <mesh filename="package://sence_leg_description/meshes/HMMR_Leg_J2_v1_1.stl" scale="0.001 0.001 0.001"/>
      </geometry>
      <material name="silver"/>
    </visual>
    <collision>
      <origin rpy="0 0 0" xyz="0.04375 0.00555 0.0"/>
      <geometry>
        <mesh filename="package://sence_leg_description/meshes/HMMR_Leg_J2_v1_1.stl" scale="0.001 0.001 0.001"/>
      </geometry>
    </collision>
  </link>
  <link name="front_left_leg_HMMR_Leg_J3_v1_1">
    <inertial>
      <origin rpy="0 0 0" xyz="-0.06366993215147018 -0.021943102238793904 0.0024098327148608222"/>
      <mass value="0.1208747488020619"/>
      <inertia ixx="3.4e-05" ixy="1.4e-05" ixz="2e-06" iyy="0.000102" iyz="-1e-06" izz="0.000104"/>
    </inertial>
    <visual>
      <origin rpy="0 0 0" xyz="0.077676 -0.00123 -0.0002"/>
      <geometry>
        <mesh filename="package://sence_leg_description/meshes/HMMR_Leg_J3_v1_1.stl" scale="0.001 0.001 0.001"/>
      </geometry>
      <material name="silver"/>
    </visual>
    <collision>
      <origin rpy="0 0 0" xyz="0.077676 -0.00123 -0.0002"/>
      <geometry>
        <mesh filename="package://sence_leg_description/meshes/HMMR_Leg_J3_v1_1.stl" scale="0.001 0.001 0.001"/>
      </geometry>
    </collision>
  </link>
  <link name="front_left_leg_HMMR_Leg_J4_1">
    <inertial>
      <origin rpy="0 0 0" xyz="-0.06827232180237036 0.01066109112327507 0.02089322420417813"/>
      <mass value="0.052701725493830516"/>
      <inertia ixx="1.8e-05" ixy="1.4e-05" ixz="-1e-06" iyy="7.3e-05" iyz="0.0" izz="7.2e-05"/>
    </inertial>
    <visual>
      <origin rpy="0 0 0" xyz="0.142683 0.01877 0.019275"/>
      <geometry>
        <mesh filename="package://sence_leg_description/meshes/HMMR_Leg_J4_1.stl" scale="0.001 0.001 0.001"/>
      </geometry>
      <material name="silver"/>
    </visual>
    <collision>
      <origin rpy="0 0 0" xyz="0.142683 0.01877 0.019275"/>
      <geometry>
        <mesh filename="package://sence_leg_description/meshes/HMMR_Leg_J4_1.stl" scale="0.001 0.001 0.001"/>
      </geometry>
    </collision>
  </link>
  <joint name="front_left_leg_system_connection" type="fixed">
    <origin rpy="3.14159 0 0" xyz="-0.20 0.15 0"/>
    <parent link="base_link"/>
    <child link="front_left_leg_base_link"/>
  </joint>
  <joint name="front_left_leg_Rev1" type="continuous">
    <origin rpy="0 0 0" xyz="-0.04375 -0.00555 0.0"/>
    <parent link="front_left_leg_base_link"/>
    <child link="front_left_leg_HMMR_Leg_J2_v1_1"/>
    <axis xyz="1.0 0.0 0.0"/>
  </joint>
  <joint name="front_left_leg_Rev2" type="revolute">
    <origin rpy="0 0 0" xyz="-0.033926 0.00678 0.0002"/>
    <parent link="front_left_leg_HMMR_Leg_J2_v1_1"/>
    <child link="front_left_leg_HMMR_Leg_J3_v1_1"/>
    <axis xyz="0.0 -1.0 0.0"/>
    <limit effort="100" lower="-1.919862" upper="1.919862" velocity="100"/>
  </joint>
  <joint name="front_left_leg_Rev3" type="revolute">
    <origin rpy="0 0 0" xyz="-0.065007 -0.02 -0.019475"/>
    <parent link="front_left_leg_HMMR_Leg_J3_v1_1"/>
    <child link="front_left_leg_HMMR_Leg_J4_1"/>
    <axis xyz="-0.0 -0.0 1.0"/>
    <limit effort="100" lower="-2.268928" upper="2.356194" velocity="100"/>
  </joint>
</robot>
