<?xml version="1.0" ?>
<!-- =================================================================================== -->
<!-- |    This document was autogenerated by xacro from /home/jovian/catkin_ws/src/sence_paper/sence_main_description/urdf/sence_comb.xacro | -->
<!-- |    EDITING THIS FILE BY HAND IS NOT RECOMMENDED                                 | -->
<!-- =================================================================================== -->
<robot name="sence_main">
  <transmission name="Rev1_tran">
    <type>transmission_interface/SimpleTransmission</type>
    <joint name="Rev1">
      <hardwareInterface>hardware_interface/EffortJointInterface</hardwareInterface>
    </joint>
    <actuator name="Rev1_actr">
      <hardwareInterface>hardware_interface/EffortJointInterface</hardwareInterface>
      <mechanicalReduction>1</mechanicalReduction>
    </actuator>
  </transmission>
  <transmission name="Rev2_tran">
    <type>transmission_interface/SimpleTransmission</type>
    <joint name="Rev2">
      <hardwareInterface>hardware_interface/EffortJointInterface</hardwareInterface>
    </joint>
    <actuator name="Rev2_actr">
      <hardwareInterface>hardware_interface/EffortJointInterface</hardwareInterface>
      <mechanicalReduction>1</mechanicalReduction>
    </actuator>
  </transmission>
  <transmission name="Rev3_tran">
    <type>transmission_interface/SimpleTransmission</type>
    <joint name="Rev5">
      <hardwareInterface>hardware_interface/EffortJointInterface</hardwareInterface>
    </joint>
    <actuator name="Rev3_actr">
      <hardwareInterface>hardware_interface/EffortJointInterface</hardwareInterface>
      <mechanicalReduction>1</mechanicalReduction>
    </actuator>
  </transmission>
  <gazebo>
    <plugin filename="libgazebo_ros_control.so" name="control"/>
  </gazebo>
  <gazebo reference="base_link">
    <material>Gazebo/Silver</material>
    <mu1>0.2</mu1>
    <mu2>0.2</mu2>
    <selfCollide>true</selfCollide>
    <gravity>true</gravity>
  </gazebo>
  <gazebo reference="HMMR_Leg_J2_v1_1">
    <material>Gazebo/Silver</material>
    <mu1>0.2</mu1>
    <mu2>0.2</mu2>
    <selfCollide>true</selfCollide>
  </gazebo>
  <gazebo reference="HMMR_Leg_J3_v1_1">
    <material>Gazebo/Silver</material>
    <mu1>0.2</mu1>
    <mu2>0.2</mu2>
    <selfCollide>true</selfCollide>
  </gazebo>
  <gazebo reference="HMMR_Leg_J4_v1_1">
    <material>Gazebo/Silver</material>
    <mu1>0.2</mu1>
    <mu2>0.2</mu2>
    <selfCollide>true</selfCollide>
  </gazebo>
  <material name="silver">
    <color rgba="0.700 0.700 0.700 1.000"/>
  </material>
  <gazebo>
    <plugin filename="libgazebo_ros_control.so" name="control"/>
  </gazebo>
  <gazebo reference="base_link">
    <material>Gazebo/Silver</material>
    <mu1>0.2</mu1>
    <mu2>0.2</mu2>
    <selfCollide>true</selfCollide>
    <gravity>true</gravity>
  </gazebo>
  <link name="base_link">
</link>
  <link name="core">
    <inertial>
      <origin rpy="0 0 0" xyz="0.00021651891376084524 -0.00010528739970071409 -0.014193022646418384"/>
      <mass value="0.4767252028506373"/>
      <inertia ixx="0.003452" ixy="3e-06" ixz="2e-06" iyy="0.000207" iyz="2e-06" izz="0.003461"/>
    </inertial>
    <visual>
      <origin rpy="0 0 0" xyz="0 0 0"/>
      <geometry>
        <mesh filename="package://sence_main_description/meshes/base_link.stl" scale="0.001 0.001 0.001"/>
      </geometry>
      <material name="silver"/>
    </visual>
    <collision>
      <origin rpy="0 0 0" xyz="0 0 0"/>
      <geometry>
        <mesh filename="package://sence_main_description/meshes/base_link.stl" scale="0.001 0.001 0.001"/>
      </geometry>
    </collision>
  </link>
  <joint name="con" type="fixed">
    <origin rpy="0 0 0" xyz="0 0 0"/>
    <parent link="base_link"/>
    <child link="core"/>
  </joint>
  <link name="back_right_leg_base_link">
    <inertial>
      <origin rpy="0 0 0" xyz="0.029044932513473305 0.010265080427010284 -0.03814827760382364"/>
      <mass value="0.15187448298114298"/>
      <inertia ixx="5.3e-05" ixy="-6e-06" ixz="0.0" iyy="6.1e-05" iyz="0.0" izz="6.9e-05"/>
    </inertial>
    <visual>
      <origin rpy="0 0 0" xyz="0 0 0"/>
      <geometry>
        <mesh filename="package://sence_leg_description/meshes/base_link.stl" scale="0.001 0.001 0.001"/>
      </geometry>
      <material name="silver"/>
    </visual>
    <collision>
      <origin rpy="0 0 0" xyz="0 0 0"/>
      <geometry>
        <mesh filename="package://sence_leg_description/meshes/base_link.stl" scale="0.001 0.001 0.001"/>
      </geometry>
    </collision>
  </link>
  <link name="back_right_leg_HMMR_Leg_J2_v1_1">
    <inertial>
      <origin rpy="0 0 0" xyz="-0.04078394902352935 -0.013231283994066126 0.00021684450055575039"/>
      <mass value="0.09734685103972182"/>
      <inertia ixx="2.2e-05" ixy="-2e-06" ixz="0.0" iyy="3.6e-05" iyz="0.0" izz="4e-05"/>
    </inertial>
    <visual>
      <origin rpy="0 0 0" xyz="-0.01348 -0.002676 0.038139"/>
      <geometry>
        <mesh filename="package://sence_leg_description/meshes/HMMR_Leg_J2_v1_1.stl" scale="0.001 0.001 0.001"/>
      </geometry>
      <material name="silver"/>
    </visual>
    <collision>
      <origin rpy="0 0 0" xyz="-0.01348 -0.002676 0.038139"/>
      <geometry>
        <mesh filename="package://sence_leg_description/meshes/HMMR_Leg_J2_v1_1.stl" scale="0.001 0.001 0.001"/>
      </geometry>
    </collision>
  </link>
  <link name="back_right_leg_HMMR_Leg_J3_v1_1">
    <inertial>
      <origin rpy="0 0 0" xyz="-0.05832553714381231 -0.021436456555043018 0.0024477833961314005"/>
      <mass value="0.12243154933451669"/>
      <inertia ixx="3.6e-05" ixy="1e-05" ixz="2e-06" iyy="9.7e-05" iyz="-0.0" izz="9.9e-05"/>
    </inertial>
    <visual>
      <origin rpy="0 0 0" xyz="0.020447 -0.009456 0.037939"/>
      <geometry>
        <mesh filename="package://sence_leg_description/meshes/HMMR_Leg_J3_v1_1.stl" scale="0.001 0.001 0.001"/>
      </geometry>
      <material name="silver"/>
    </visual>
    <collision>
      <origin rpy="0 0 0" xyz="0.020447 -0.009456 0.037939"/>
      <geometry>
        <mesh filename="package://sence_leg_description/meshes/HMMR_Leg_J3_v1_1.stl" scale="0.001 0.001 0.001"/>
      </geometry>
    </collision>
  </link>
  <link name="back_right_leg_HMMR_Leg_J4_1">
    <inertial>
      <origin rpy="0 0 0" xyz="-0.05691796302157942 0.007704167559869515 0.01964749184467182"/>
      <mass value="0.05742201556545181"/>
      <inertia ixx="2e-05" ixy="8e-06" ixz="1e-06" iyy="5.7e-05" iyz="-0.0" izz="5.2e-05"/>
    </inertial>
    <visual>
      <origin rpy="0 0 0" xyz="0.079954 0.010544 0.057414"/>
      <geometry>
        <mesh filename="package://sence_leg_description/meshes/HMMR_Leg_J4_v1_1.stl" scale="0.001 0.001 0.001"/>
      </geometry>
      <material name="silver"/>
    </visual>
    <collision>
      <origin rpy="0 0 0" xyz="0.079954 0.010544 0.057414"/>
      <geometry>
        <mesh filename="package://sence_leg_description/meshes/HMMR_Leg_J4_v1_1.stl" scale="0.001 0.001 0.001"/>
      </geometry>
    </collision>
  </link>
  <joint name="back_right_leg_system_connection" type="fixed">
    <origin rpy="0 3.14159 0" xyz="0.0826 -0.105095 -0.05196"/>
    <parent link="core"/>
    <child link="back_right_leg_base_link"/>
  </joint>
  <joint name="back_right_leg_Rev1" type="continuous">
    <origin rpy="0 0 0" xyz="0.01348 0.002676 -0.038139"/>
    <parent link="back_right_leg_base_link"/>
    <child link="back_right_leg_HMMR_Leg_J2_v1_1"/>
    <axis xyz="1.0 0.0 -0.0"/>
  </joint>
  <joint name="back_right_leg_Rev2" type="revolute">
    <origin rpy="0 0 0" xyz="-0.033927 0.00678 0.0002"/>
    <parent link="back_right_leg_HMMR_Leg_J2_v1_1"/>
    <child link="back_right_leg_HMMR_Leg_J3_v1_1"/>
    <axis xyz="0.0 -1.0 0.0"/>
    <limit effort="100" lower="-1.919862" upper="1.919862" velocity="100"/>
  </joint>
  <joint name="back_right_leg_Rev3" type="revolute">
    <origin rpy="0 0 0" xyz="-0.059507 -0.02 -0.019475"/>
    <parent link="back_right_leg_HMMR_Leg_J3_v1_1"/>
    <child link="back_right_leg_HMMR_Leg_J4_1"/>
    <axis xyz="-0.0 -0.0 1.0"/>
    <limit effort="100" lower="-2.094395" upper="2.094395" velocity="100"/>
  </joint>
  <link name="back_left_leg_base_link">
    <inertial>
      <origin rpy="0 0 0" xyz="0.029044932513473305 0.010265080427010284 -0.03814827760382364"/>
      <mass value="0.15187448298114298"/>
      <inertia ixx="5.3e-05" ixy="-6e-06" ixz="0.0" iyy="6.1e-05" iyz="0.0" izz="6.9e-05"/>
    </inertial>
    <visual>
      <origin rpy="0 0 0" xyz="0 0 0"/>
      <geometry>
        <mesh filename="package://sence_leg_description/meshes/base_link.stl" scale="0.001 0.001 0.001"/>
      </geometry>
      <material name="silver"/>
    </visual>
    <collision>
      <origin rpy="0 0 0" xyz="0 0 0"/>
      <geometry>
        <mesh filename="package://sence_leg_description/meshes/base_link.stl" scale="0.001 0.001 0.001"/>
      </geometry>
    </collision>
  </link>
  <link name="back_left_leg_HMMR_Leg_J2_v1_1">
    <inertial>
      <origin rpy="0 0 0" xyz="-0.04078394902352935 -0.013231283994066126 0.00021684450055575039"/>
      <mass value="0.09734685103972182"/>
      <inertia ixx="2.2e-05" ixy="-2e-06" ixz="0.0" iyy="3.6e-05" iyz="0.0" izz="4e-05"/>
    </inertial>
    <visual>
      <origin rpy="0 0 0" xyz="-0.01348 -0.002676 0.038139"/>
      <geometry>
        <mesh filename="package://sence_leg_description/meshes/HMMR_Leg_J2_v1_1.stl" scale="0.001 0.001 0.001"/>
      </geometry>
      <material name="silver"/>
    </visual>
    <collision>
      <origin rpy="0 0 0" xyz="-0.01348 -0.002676 0.038139"/>
      <geometry>
        <mesh filename="package://sence_leg_description/meshes/HMMR_Leg_J2_v1_1.stl" scale="0.001 0.001 0.001"/>
      </geometry>
    </collision>
  </link>
  <link name="back_left_leg_HMMR_Leg_J3_v1_1">
    <inertial>
      <origin rpy="0 0 0" xyz="-0.05832553714381231 -0.021436456555043018 0.0024477833961314005"/>
      <mass value="0.12243154933451669"/>
      <inertia ixx="3.6e-05" ixy="1e-05" ixz="2e-06" iyy="9.7e-05" iyz="-0.0" izz="9.9e-05"/>
    </inertial>
    <visual>
      <origin rpy="0 0 0" xyz="0.020447 -0.009456 0.037939"/>
      <geometry>
        <mesh filename="package://sence_leg_description/meshes/HMMR_Leg_J3_v1_1.stl" scale="0.001 0.001 0.001"/>
      </geometry>
      <material name="silver"/>
    </visual>
    <collision>
      <origin rpy="0 0 0" xyz="0.020447 -0.009456 0.037939"/>
      <geometry>
        <mesh filename="package://sence_leg_description/meshes/HMMR_Leg_J3_v1_1.stl" scale="0.001 0.001 0.001"/>
      </geometry>
    </collision>
  </link>
  <link name="back_left_leg_HMMR_Leg_J4_1">
    <inertial>
      <origin rpy="0 0 0" xyz="-0.05691796302157942 0.007704167559869515 0.01964749184467182"/>
      <mass value="0.05742201556545181"/>
      <inertia ixx="2e-05" ixy="8e-06" ixz="1e-06" iyy="5.7e-05" iyz="-0.0" izz="5.2e-05"/>
    </inertial>
    <visual>
      <origin rpy="0 0 0" xyz="0.079954 0.010544 0.057414"/>
      <geometry>
        <mesh filename="package://sence_leg_description/meshes/HMMR_Leg_J4_v1_1.stl" scale="0.001 0.001 0.001"/>
      </geometry>
      <material name="silver"/>
    </visual>
    <collision>
      <origin rpy="0 0 0" xyz="0.079954 0.010544 0.057414"/>
      <geometry>
        <mesh filename="package://sence_leg_description/meshes/HMMR_Leg_J4_v1_1.stl" scale="0.001 0.001 0.001"/>
      </geometry>
    </collision>
  </link>
  <joint name="back_left_leg_system_connection" type="fixed">
    <origin rpy="0 0 0" xyz="-0.0826 -0.105095 0.024316"/>
    <parent link="core"/>
    <child link="back_left_leg_base_link"/>
  </joint>
  <joint name="back_left_leg_Rev1" type="continuous">
    <origin rpy="0 0 0" xyz="0.01348 0.002676 -0.038139"/>
    <parent link="back_left_leg_base_link"/>
    <child link="back_left_leg_HMMR_Leg_J2_v1_1"/>
    <axis xyz="1.0 0.0 -0.0"/>
  </joint>
  <joint name="back_left_leg_Rev2" type="revolute">
    <origin rpy="0 0 0" xyz="-0.033927 0.00678 0.0002"/>
    <parent link="back_left_leg_HMMR_Leg_J2_v1_1"/>
    <child link="back_left_leg_HMMR_Leg_J3_v1_1"/>
    <axis xyz="0.0 -1.0 0.0"/>
    <limit effort="100" lower="-1.919862" upper="1.919862" velocity="100"/>
  </joint>
  <joint name="back_left_leg_Rev3" type="revolute">
    <origin rpy="0 0 0" xyz="-0.059507 -0.02 -0.019475"/>
    <parent link="back_left_leg_HMMR_Leg_J3_v1_1"/>
    <child link="back_left_leg_HMMR_Leg_J4_1"/>
    <axis xyz="-0.0 -0.0 1.0"/>
    <limit effort="100" lower="-2.094395" upper="2.094395" velocity="100"/>
  </joint>
  <link name="front_right_leg_base_link">
    <inertial>
      <origin rpy="0 0 0" xyz="0.029044932513473305 0.010265080427010284 -0.03814827760382364"/>
      <mass value="0.15187448298114298"/>
      <inertia ixx="5.3e-05" ixy="-6e-06" ixz="0.0" iyy="6.1e-05" iyz="0.0" izz="6.9e-05"/>
    </inertial>
    <visual>
      <origin rpy="0 0 0" xyz="0 0 0"/>
      <geometry>
        <mesh filename="package://sence_leg_description/meshes/base_link.stl" scale="0.001 0.001 0.001"/>
      </geometry>
      <material name="silver"/>
    </visual>
    <collision>
      <origin rpy="0 0 0" xyz="0 0 0"/>
      <geometry>
        <mesh filename="package://sence_leg_description/meshes/base_link.stl" scale="0.001 0.001 0.001"/>
      </geometry>
    </collision>
  </link>
  <link name="front_right_leg_HMMR_Leg_J2_v1_1">
    <inertial>
      <origin rpy="0 0 0" xyz="-0.04078394902352935 -0.013231283994066126 0.00021684450055575039"/>
      <mass value="0.09734685103972182"/>
      <inertia ixx="2.2e-05" ixy="-2e-06" ixz="0.0" iyy="3.6e-05" iyz="0.0" izz="4e-05"/>
    </inertial>
    <visual>
      <origin rpy="0 0 0" xyz="-0.01348 -0.002676 0.038139"/>
      <geometry>
        <mesh filename="package://sence_leg_description/meshes/HMMR_Leg_J2_v1_1.stl" scale="0.001 0.001 0.001"/>
      </geometry>
      <material name="silver"/>
    </visual>
    <collision>
      <origin rpy="0 0 0" xyz="-0.01348 -0.002676 0.038139"/>
      <geometry>
        <mesh filename="package://sence_leg_description/meshes/HMMR_Leg_J2_v1_1.stl" scale="0.001 0.001 0.001"/>
      </geometry>
    </collision>
  </link>
  <link name="front_right_leg_HMMR_Leg_J3_v1_1">
    <inertial>
      <origin rpy="0 0 0" xyz="-0.05832553714381231 -0.021436456555043018 0.0024477833961314005"/>
      <mass value="0.12243154933451669"/>
      <inertia ixx="3.6e-05" ixy="1e-05" ixz="2e-06" iyy="9.7e-05" iyz="-0.0" izz="9.9e-05"/>
    </inertial>
    <visual>
      <origin rpy="0 0 0" xyz="0.020447 -0.009456 0.037939"/>
      <geometry>
        <mesh filename="package://sence_leg_description/meshes/HMMR_Leg_J3_v1_1.stl" scale="0.001 0.001 0.001"/>
      </geometry>
      <material name="silver"/>
    </visual>
    <collision>
      <origin rpy="0 0 0" xyz="0.020447 -0.009456 0.037939"/>
      <geometry>
        <mesh filename="package://sence_leg_description/meshes/HMMR_Leg_J3_v1_1.stl" scale="0.001 0.001 0.001"/>
      </geometry>
    </collision>
  </link>
  <link name="front_right_leg_HMMR_Leg_J4_1">
    <inertial>
      <origin rpy="0 0 0" xyz="-0.05691796302157942 0.007704167559869515 0.01964749184467182"/>
      <mass value="0.05742201556545181"/>
      <inertia ixx="2e-05" ixy="8e-06" ixz="1e-06" iyy="5.7e-05" iyz="-0.0" izz="5.2e-05"/>
    </inertial>
    <visual>
      <origin rpy="0 0 0" xyz="0.079954 0.010544 0.057414"/>
      <geometry>
        <mesh filename="package://sence_leg_description/meshes/HMMR_Leg_J4_v1_1.stl" scale="0.001 0.001 0.001"/>
      </geometry>
      <material name="silver"/>
    </visual>
    <collision>
      <origin rpy="0 0 0" xyz="0.079954 0.010544 0.057414"/>
      <geometry>
        <mesh filename="package://sence_leg_description/meshes/HMMR_Leg_J4_v1_1.stl" scale="0.001 0.001 0.001"/>
      </geometry>
    </collision>
  </link>
  <joint name="front_right_leg_system_connection" type="fixed">
    <origin rpy="3.14159 3.14159 0" xyz="0.0826 0.105095 0.024316"/>
    <parent link="core"/>
    <child link="front_right_leg_base_link"/>
  </joint>
  <joint name="front_right_leg_Rev1" type="continuous">
    <origin rpy="0 0 0" xyz="0.01348 0.002676 -0.038139"/>
    <parent link="front_right_leg_base_link"/>
    <child link="front_right_leg_HMMR_Leg_J2_v1_1"/>
    <axis xyz="1.0 0.0 -0.0"/>
  </joint>
  <joint name="front_right_leg_Rev2" type="revolute">
    <origin rpy="0 0 0" xyz="-0.033927 0.00678 0.0002"/>
    <parent link="front_right_leg_HMMR_Leg_J2_v1_1"/>
    <child link="front_right_leg_HMMR_Leg_J3_v1_1"/>
    <axis xyz="0.0 -1.0 0.0"/>
    <limit effort="100" lower="-1.919862" upper="1.919862" velocity="100"/>
  </joint>
  <joint name="front_right_leg_Rev3" type="revolute">
    <origin rpy="0 0 0" xyz="-0.059507 -0.02 -0.019475"/>
    <parent link="front_right_leg_HMMR_Leg_J3_v1_1"/>
    <child link="front_right_leg_HMMR_Leg_J4_1"/>
    <axis xyz="-0.0 -0.0 1.0"/>
    <limit effort="100" lower="-2.094395" upper="2.094395" velocity="100"/>
  </joint>
  <link name="front_left_leg_base_link">
    <inertial>
      <origin rpy="0 0 0" xyz="0.029044932513473305 0.010265080427010284 -0.03814827760382364"/>
      <mass value="0.15187448298114298"/>
      <inertia ixx="5.3e-05" ixy="-6e-06" ixz="0.0" iyy="6.1e-05" iyz="0.0" izz="6.9e-05"/>
    </inertial>
    <visual>
      <origin rpy="0 0 0" xyz="0 0 0"/>
      <geometry>
        <mesh filename="package://sence_leg_description/meshes/base_link.stl" scale="0.001 0.001 0.001"/>
      </geometry>
      <material name="silver"/>
    </visual>
    <collision>
      <origin rpy="0 0 0" xyz="0 0 0"/>
      <geometry>
        <mesh filename="package://sence_leg_description/meshes/base_link.stl" scale="0.001 0.001 0.001"/>
      </geometry>
    </collision>
  </link>
  <link name="front_left_leg_HMMR_Leg_J2_v1_1">
    <inertial>
      <origin rpy="0 0 0" xyz="-0.04078394902352935 -0.013231283994066126 0.00021684450055575039"/>
      <mass value="0.09734685103972182"/>
      <inertia ixx="2.2e-05" ixy="-2e-06" ixz="0.0" iyy="3.6e-05" iyz="0.0" izz="4e-05"/>
    </inertial>
    <visual>
      <origin rpy="0 0 0" xyz="-0.01348 -0.002676 0.038139"/>
      <geometry>
        <mesh filename="package://sence_leg_description/meshes/HMMR_Leg_J2_v1_1.stl" scale="0.001 0.001 0.001"/>
      </geometry>
      <material name="silver"/>
    </visual>
    <collision>
      <origin rpy="0 0 0" xyz="-0.01348 -0.002676 0.038139"/>
      <geometry>
        <mesh filename="package://sence_leg_description/meshes/HMMR_Leg_J2_v1_1.stl" scale="0.001 0.001 0.001"/>
      </geometry>
    </collision>
  </link>
  <link name="front_left_leg_HMMR_Leg_J3_v1_1">
    <inertial>
      <origin rpy="0 0 0" xyz="-0.05832553714381231 -0.021436456555043018 0.0024477833961314005"/>
      <mass value="0.12243154933451669"/>
      <inertia ixx="3.6e-05" ixy="1e-05" ixz="2e-06" iyy="9.7e-05" iyz="-0.0" izz="9.9e-05"/>
    </inertial>
    <visual>
      <origin rpy="0 0 0" xyz="0.020447 -0.009456 0.037939"/>
      <geometry>
        <mesh filename="package://sence_leg_description/meshes/HMMR_Leg_J3_v1_1.stl" scale="0.001 0.001 0.001"/>
      </geometry>
      <material name="silver"/>
    </visual>
    <collision>
      <origin rpy="0 0 0" xyz="0.020447 -0.009456 0.037939"/>
      <geometry>
        <mesh filename="package://sence_leg_description/meshes/HMMR_Leg_J3_v1_1.stl" scale="0.001 0.001 0.001"/>
      </geometry>
    </collision>
  </link>
  <link name="front_left_leg_HMMR_Leg_J4_1">
    <inertial>
      <origin rpy="0 0 0" xyz="-0.05691796302157942 0.007704167559869515 0.01964749184467182"/>
      <mass value="0.05742201556545181"/>
      <inertia ixx="2e-05" ixy="8e-06" ixz="1e-06" iyy="5.7e-05" iyz="-0.0" izz="5.2e-05"/>
    </inertial>
    <visual>
      <origin rpy="0 0 0" xyz="0.079954 0.010544 0.057414"/>
      <geometry>
        <mesh filename="package://sence_leg_description/meshes/HMMR_Leg_J4_v1_1.stl" scale="0.001 0.001 0.001"/>
      </geometry>
      <material name="silver"/>
    </visual>
    <collision>
      <origin rpy="0 0 0" xyz="0.079954 0.010544 0.057414"/>
      <geometry>
        <mesh filename="package://sence_leg_description/meshes/HMMR_Leg_J4_v1_1.stl" scale="0.001 0.001 0.001"/>
      </geometry>
    </collision>
  </link>
  <joint name="front_left_leg_system_connection" type="fixed">
    <origin rpy="3.14159 0 0" xyz="-0.0826 0.105095 -0.05196"/>
    <parent link="core"/>
    <child link="front_left_leg_base_link"/>
  </joint>
  <joint name="front_left_leg_Rev1" type="continuous">
    <origin rpy="0 0 0" xyz="0.01348 0.002676 -0.038139"/>
    <parent link="front_left_leg_base_link"/>
    <child link="front_left_leg_HMMR_Leg_J2_v1_1"/>
    <axis xyz="1.0 0.0 -0.0"/>
  </joint>
  <joint name="front_left_leg_Rev2" type="revolute">
    <origin rpy="0 0 0" xyz="-0.033927 0.00678 0.0002"/>
    <parent link="front_left_leg_HMMR_Leg_J2_v1_1"/>
    <child link="front_left_leg_HMMR_Leg_J3_v1_1"/>
    <axis xyz="0.0 -1.0 0.0"/>
    <limit effort="100" lower="-1.919862" upper="1.919862" velocity="100"/>
  </joint>
  <joint name="front_left_leg_Rev3" type="revolute">
    <origin rpy="0 0 0" xyz="-0.059507 -0.02 -0.019475"/>
    <parent link="front_left_leg_HMMR_Leg_J3_v1_1"/>
    <child link="front_left_leg_HMMR_Leg_J4_1"/>
    <axis xyz="-0.0 -0.0 1.0"/>
    <limit effort="100" lower="-2.094395" upper="2.094395" velocity="100"/>
  </joint>
</robot>
